INFO:uvicorn.error:Started server process [7872]
INFO:uvicorn.error:Waiting for application startup.
INFO:uvicorn.error:Application startup complete.
INFO:uvicorn.error:Started server process [5328]
INFO:uvicorn.error:Waiting for application startup.
INFO:uvicorn.error:Application startup complete.
ERROR:app.routes.user:Non-existent user_id: 1 was requested
INFO:uvicorn.error:Started server process [12452]
INFO:uvicorn.error:Waiting for application startup.
INFO:uvicorn.error:Application startup complete.
INFO:app.routes.user:About to delete user_id: 0
INFO:uvicorn.error:Started server process [10780]
INFO:uvicorn.error:Waiting for application startup.
INFO:uvicorn.error:Application startup complete.
INFO:uvicorn.error:Started server process [12272]
INFO:uvicorn.error:Waiting for application startup.
INFO:uvicorn.error:Application startup complete.
INFO:uvicorn.error:Started server process [7108]
INFO:uvicorn.error:Waiting for application startup.
INFO:uvicorn.error:Application startup complete.
INFO:uvicorn.error:Started server process [2620]
INFO:uvicorn.error:Waiting for application startup.
INFO:uvicorn.error:Application startup complete.
INFO:uvicorn.error:Started server process [4176]
INFO:uvicorn.error:Waiting for application startup.
INFO:uvicorn.error:Application startup complete.
INFO:uvicorn.error:Started server process [7940]
INFO:uvicorn.error:Waiting for application startup.
INFO:uvicorn.error:Application startup complete.
INFO:uvicorn.error:Started server process [8612]
INFO:uvicorn.error:Waiting for application startup.
INFO:uvicorn.error:Application startup complete.
INFO:uvicorn.error:Started server process [13244]
INFO:uvicorn.error:Waiting for application startup.
INFO:uvicorn.error:Application startup complete.
ERROR:app.routes.user:Non-existent user_id: 1 was requested
INFO:uvicorn.error:Started server process [1872]
INFO:uvicorn.error:Waiting for application startup.
INFO:uvicorn.error:Application startup complete.
INFO:uvicorn.error:Started server process [14768]
INFO:uvicorn.error:Waiting for application startup.
INFO:uvicorn.error:Application startup complete.
INFO uvicorn.error 2023-07-20 22:05:23,535 Started server process [1260]
INFO uvicorn.error 2023-07-20 22:05:23,540 Waiting for application startup.
INFO uvicorn.error 2023-07-20 22:05:23,542 Application startup complete.
ERROR app.routes.user 2023-07-20 22:05:38,908 Non-existent user_id: 1 was requested
INFO   uvicorn.error 2023-07-20 22:06:42,672 Started server process [4144]
INFO   uvicorn.error 2023-07-20 22:06:42,675 Waiting for application startup.
INFO   uvicorn.error 2023-07-20 22:06:42,678 Application startup complete.
INFO   uvicorn.error   2023-07-20 22:06:48,262 Started server process [2952]
INFO   uvicorn.error   2023-07-20 22:06:48,263 Waiting for application startup.
INFO   uvicorn.error   2023-07-20 22:06:48,263 Application startup complete.
ERROR  app.routes.user 2023-07-20 22:06:48,424 Non-existent user_id: 1 was requested
INFO   uvicorn.error   23-07-20 Started server process [10300]
INFO   uvicorn.error   23-07-20 Waiting for application startup.
INFO   uvicorn.error   23-07-20 Application startup complete.
INFO   uvicorn.error   23-07-20 22:08:57 Started server process [13484]
INFO   uvicorn.error   23-07-20 22:08:57 Waiting for application startup.
INFO   uvicorn.error   23-07-20 22:08:57 Application startup complete.
INFO   uvicorn.error   23-07-20 22:09:47.345 Started server process [3120]
INFO   uvicorn.error   23-07-20 22:09:47.345 Waiting for application startup.
INFO   uvicorn.error   23-07-20 22:09:47.346 Application startup complete.
INFO   uvicorn.error   23-07-20 22:20:33.156 Started server process [12908]
INFO   uvicorn.error   23-07-20 22:20:33.171 Waiting for application startup.
INFO   uvicorn.error   23-07-20 22:20:33.179 Application startup complete.
ERROR  uvicorn.error   23-07-20 22:21:01.961 Exception in ASGI application
Traceback (most recent call last):
  File "C:\Users\tobis\AppData\Local\Packages\PythonSoftwareFoundation.Python.3.7_qbz5n2kfra8p0\LocalCache\local-packages\Python37\site-packages\uvicorn\protocols\http\httptools_impl.py", line 401, in run_asgi
    result = await app(self.scope, self.receive, self.send)
  File "C:\Users\tobis\AppData\Local\Packages\PythonSoftwareFoundation.Python.3.7_qbz5n2kfra8p0\LocalCache\local-packages\Python37\site-packages\uvicorn\middleware\proxy_headers.py", line 78, in __call__
    return await self.app(scope, receive, send)
  File "C:\Users\tobis\AppData\Local\Packages\PythonSoftwareFoundation.Python.3.7_qbz5n2kfra8p0\LocalCache\local-packages\Python37\site-packages\fastapi\applications.py", line 269, in __call__
    await super().__call__(scope, receive, send)
  File "C:\Users\tobis\AppData\Local\Packages\PythonSoftwareFoundation.Python.3.7_qbz5n2kfra8p0\LocalCache\local-packages\Python37\site-packages\starlette\applications.py", line 124, in __call__
    await self.middleware_stack(scope, receive, send)
  File "C:\Users\tobis\AppData\Local\Packages\PythonSoftwareFoundation.Python.3.7_qbz5n2kfra8p0\LocalCache\local-packages\Python37\site-packages\starlette\middleware\errors.py", line 184, in __call__
    raise exc
  File "C:\Users\tobis\AppData\Local\Packages\PythonSoftwareFoundation.Python.3.7_qbz5n2kfra8p0\LocalCache\local-packages\Python37\site-packages\starlette\middleware\errors.py", line 162, in __call__
    await self.app(scope, receive, _send)
  File "C:\Users\tobis\AppData\Local\Packages\PythonSoftwareFoundation.Python.3.7_qbz5n2kfra8p0\LocalCache\local-packages\Python37\site-packages\starlette\exceptions.py", line 93, in __call__
    raise exc
  File "C:\Users\tobis\AppData\Local\Packages\PythonSoftwareFoundation.Python.3.7_qbz5n2kfra8p0\LocalCache\local-packages\Python37\site-packages\starlette\exceptions.py", line 82, in __call__
    await self.app(scope, receive, sender)
  File "C:\Users\tobis\AppData\Local\Packages\PythonSoftwareFoundation.Python.3.7_qbz5n2kfra8p0\LocalCache\local-packages\Python37\site-packages\fastapi\middleware\asyncexitstack.py", line 21, in __call__
    raise e
  File "C:\Users\tobis\AppData\Local\Packages\PythonSoftwareFoundation.Python.3.7_qbz5n2kfra8p0\LocalCache\local-packages\Python37\site-packages\fastapi\middleware\asyncexitstack.py", line 18, in __call__
    await self.app(scope, receive, send)
  File "C:\Users\tobis\AppData\Local\Packages\PythonSoftwareFoundation.Python.3.7_qbz5n2kfra8p0\LocalCache\local-packages\Python37\site-packages\starlette\routing.py", line 670, in __call__
    await route.handle(scope, receive, send)
  File "C:\Users\tobis\AppData\Local\Packages\PythonSoftwareFoundation.Python.3.7_qbz5n2kfra8p0\LocalCache\local-packages\Python37\site-packages\starlette\routing.py", line 266, in handle
    await self.app(scope, receive, send)
  File "C:\Users\tobis\AppData\Local\Packages\PythonSoftwareFoundation.Python.3.7_qbz5n2kfra8p0\LocalCache\local-packages\Python37\site-packages\starlette\routing.py", line 65, in app
    response = await func(request)
  File "C:\Users\tobis\AppData\Local\Packages\PythonSoftwareFoundation.Python.3.7_qbz5n2kfra8p0\LocalCache\local-packages\Python37\site-packages\fastapi\routing.py", line 228, in app
    dependant=dependant, values=values, is_coroutine=is_coroutine
  File "C:\Users\tobis\AppData\Local\Packages\PythonSoftwareFoundation.Python.3.7_qbz5n2kfra8p0\LocalCache\local-packages\Python37\site-packages\fastapi\routing.py", line 160, in run_endpoint_function
    return await dependant.call(**values)
  File ".\app\routes\user.py", line 37, in get_user_by_id
    full_user_profile = await user_service.get_user_info(user_id)
  File ".\app\services\user.py", line 44, in get_user_info
    raise UserNotFound
app.exceptions.UserNotFound
INFO   uvicorn.error   23-07-20 22:23:27.687 Started server process [5420]
INFO   uvicorn.error   23-07-20 22:23:27.688 Waiting for application startup.
INFO   uvicorn.error   23-07-20 22:23:27.689 Application startup complete.
INFO   uvicorn.error   23-07-20 22:24:04.854 Started server process [7984]
INFO   uvicorn.error   23-07-20 22:24:04.874 Waiting for application startup.
INFO   uvicorn.error   23-07-20 22:24:04.885 Application startup complete.
INFO   uvicorn.error   23-07-20 22:24:26.930 Started server process [14440]
INFO   uvicorn.error   23-07-20 22:24:26.932 Waiting for application startup.
INFO   uvicorn.error   23-07-20 22:24:26.933 Application startup complete.
INFO   uvicorn.error   23-07-20 22:24:32.929 Started server process [5092]
INFO   uvicorn.error   23-07-20 22:24:32.930 Waiting for application startup.
INFO   uvicorn.error   23-07-20 22:24:32.931 Application startup complete.
ERROR  uvicorn.error   23-07-20 22:24:39.915 Exception in ASGI application
Traceback (most recent call last):
  File "C:\Users\tobis\AppData\Local\Packages\PythonSoftwareFoundation.Python.3.7_qbz5n2kfra8p0\LocalCache\local-packages\Python37\site-packages\starlette\exceptions.py", line 82, in __call__
    await self.app(scope, receive, sender)
  File "C:\Users\tobis\AppData\Local\Packages\PythonSoftwareFoundation.Python.3.7_qbz5n2kfra8p0\LocalCache\local-packages\Python37\site-packages\fastapi\middleware\asyncexitstack.py", line 21, in __call__
    raise e
  File "C:\Users\tobis\AppData\Local\Packages\PythonSoftwareFoundation.Python.3.7_qbz5n2kfra8p0\LocalCache\local-packages\Python37\site-packages\fastapi\middleware\asyncexitstack.py", line 18, in __call__
    await self.app(scope, receive, send)
  File "C:\Users\tobis\AppData\Local\Packages\PythonSoftwareFoundation.Python.3.7_qbz5n2kfra8p0\LocalCache\local-packages\Python37\site-packages\starlette\routing.py", line 670, in __call__
    await route.handle(scope, receive, send)
  File "C:\Users\tobis\AppData\Local\Packages\PythonSoftwareFoundation.Python.3.7_qbz5n2kfra8p0\LocalCache\local-packages\Python37\site-packages\starlette\routing.py", line 266, in handle
    await self.app(scope, receive, send)
  File "C:\Users\tobis\AppData\Local\Packages\PythonSoftwareFoundation.Python.3.7_qbz5n2kfra8p0\LocalCache\local-packages\Python37\site-packages\starlette\routing.py", line 65, in app
    response = await func(request)
  File "C:\Users\tobis\AppData\Local\Packages\PythonSoftwareFoundation.Python.3.7_qbz5n2kfra8p0\LocalCache\local-packages\Python37\site-packages\fastapi\routing.py", line 228, in app
    dependant=dependant, values=values, is_coroutine=is_coroutine
  File "C:\Users\tobis\AppData\Local\Packages\PythonSoftwareFoundation.Python.3.7_qbz5n2kfra8p0\LocalCache\local-packages\Python37\site-packages\fastapi\routing.py", line 160, in run_endpoint_function
    return await dependant.call(**values)
  File ".\app\routes\user.py", line 37, in get_user_by_id
    full_user_profile = await user_service.get_user_info(user_id)
  File ".\app\services\user.py", line 44, in get_user_info
    raise UserNotFound
app.exceptions.UserNotFound

During handling of the above exception, another exception occurred:

Traceback (most recent call last):
  File "C:\Users\tobis\AppData\Local\Packages\PythonSoftwareFoundation.Python.3.7_qbz5n2kfra8p0\LocalCache\local-packages\Python37\site-packages\uvicorn\protocols\http\httptools_impl.py", line 401, in run_asgi
    result = await app(self.scope, self.receive, self.send)
  File "C:\Users\tobis\AppData\Local\Packages\PythonSoftwareFoundation.Python.3.7_qbz5n2kfra8p0\LocalCache\local-packages\Python37\site-packages\uvicorn\middleware\proxy_headers.py", line 78, in __call__
    return await self.app(scope, receive, send)
  File "C:\Users\tobis\AppData\Local\Packages\PythonSoftwareFoundation.Python.3.7_qbz5n2kfra8p0\LocalCache\local-packages\Python37\site-packages\fastapi\applications.py", line 269, in __call__
    await super().__call__(scope, receive, send)
  File "C:\Users\tobis\AppData\Local\Packages\PythonSoftwareFoundation.Python.3.7_qbz5n2kfra8p0\LocalCache\local-packages\Python37\site-packages\starlette\applications.py", line 124, in __call__
    await self.middleware_stack(scope, receive, send)
  File "C:\Users\tobis\AppData\Local\Packages\PythonSoftwareFoundation.Python.3.7_qbz5n2kfra8p0\LocalCache\local-packages\Python37\site-packages\starlette\middleware\errors.py", line 184, in __call__
    raise exc
  File "C:\Users\tobis\AppData\Local\Packages\PythonSoftwareFoundation.Python.3.7_qbz5n2kfra8p0\LocalCache\local-packages\Python37\site-packages\starlette\middleware\errors.py", line 162, in __call__
    await self.app(scope, receive, _send)
  File "C:\Users\tobis\AppData\Local\Packages\PythonSoftwareFoundation.Python.3.7_qbz5n2kfra8p0\LocalCache\local-packages\Python37\site-packages\starlette\exceptions.py", line 101, in __call__
    response = await handler(request, exc)
  File ".\main.py", line 14, in handle_user_not_found_exception
    raise HTTPException(status_code=404, detail="User does not exist")
fastapi.exceptions.HTTPException
INFO   uvicorn.error   23-07-20 22:25:19.387 Started server process [9596]
INFO   uvicorn.error   23-07-20 22:25:19.390 Waiting for application startup.
INFO   uvicorn.error   23-07-20 22:25:19.392 Application startup complete.
INFO   uvicorn.error   23-07-20 22:25:27.368 Started server process [12560]
INFO   uvicorn.error   23-07-20 22:25:27.370 Waiting for application startup.
INFO   uvicorn.error   23-07-20 22:25:27.371 Application startup complete.
INFO   uvicorn.error   23-07-20 22:25:39.850 Started server process [11948]
INFO   uvicorn.error   23-07-20 22:25:39.853 Waiting for application startup.
INFO   uvicorn.error   23-07-20 22:25:39.854 Application startup complete.
ERROR  uvicorn.error   23-07-20 22:25:44.648 Exception in ASGI application
Traceback (most recent call last):
  File "C:\Users\tobis\AppData\Local\Packages\PythonSoftwareFoundation.Python.3.7_qbz5n2kfra8p0\LocalCache\local-packages\Python37\site-packages\starlette\exceptions.py", line 82, in __call__
    await self.app(scope, receive, sender)
  File "C:\Users\tobis\AppData\Local\Packages\PythonSoftwareFoundation.Python.3.7_qbz5n2kfra8p0\LocalCache\local-packages\Python37\site-packages\fastapi\middleware\asyncexitstack.py", line 21, in __call__
    raise e
  File "C:\Users\tobis\AppData\Local\Packages\PythonSoftwareFoundation.Python.3.7_qbz5n2kfra8p0\LocalCache\local-packages\Python37\site-packages\fastapi\middleware\asyncexitstack.py", line 18, in __call__
    await self.app(scope, receive, send)
  File "C:\Users\tobis\AppData\Local\Packages\PythonSoftwareFoundation.Python.3.7_qbz5n2kfra8p0\LocalCache\local-packages\Python37\site-packages\starlette\routing.py", line 670, in __call__
    await route.handle(scope, receive, send)
  File "C:\Users\tobis\AppData\Local\Packages\PythonSoftwareFoundation.Python.3.7_qbz5n2kfra8p0\LocalCache\local-packages\Python37\site-packages\starlette\routing.py", line 266, in handle
    await self.app(scope, receive, send)
  File "C:\Users\tobis\AppData\Local\Packages\PythonSoftwareFoundation.Python.3.7_qbz5n2kfra8p0\LocalCache\local-packages\Python37\site-packages\starlette\routing.py", line 65, in app
    response = await func(request)
  File "C:\Users\tobis\AppData\Local\Packages\PythonSoftwareFoundation.Python.3.7_qbz5n2kfra8p0\LocalCache\local-packages\Python37\site-packages\fastapi\routing.py", line 228, in app
    dependant=dependant, values=values, is_coroutine=is_coroutine
  File "C:\Users\tobis\AppData\Local\Packages\PythonSoftwareFoundation.Python.3.7_qbz5n2kfra8p0\LocalCache\local-packages\Python37\site-packages\fastapi\routing.py", line 160, in run_endpoint_function
    return await dependant.call(**values)
  File ".\app\routes\user.py", line 37, in get_user_by_id
    full_user_profile = await user_service.get_user_info(user_id)
  File ".\app\services\user.py", line 44, in get_user_info
    raise UserNotFound
app.exceptions.UserNotFound

During handling of the above exception, another exception occurred:

Traceback (most recent call last):
  File "C:\Users\tobis\AppData\Local\Packages\PythonSoftwareFoundation.Python.3.7_qbz5n2kfra8p0\LocalCache\local-packages\Python37\site-packages\uvicorn\protocols\http\httptools_impl.py", line 401, in run_asgi
    result = await app(self.scope, self.receive, self.send)
  File "C:\Users\tobis\AppData\Local\Packages\PythonSoftwareFoundation.Python.3.7_qbz5n2kfra8p0\LocalCache\local-packages\Python37\site-packages\uvicorn\middleware\proxy_headers.py", line 78, in __call__
    return await self.app(scope, receive, send)
  File "C:\Users\tobis\AppData\Local\Packages\PythonSoftwareFoundation.Python.3.7_qbz5n2kfra8p0\LocalCache\local-packages\Python37\site-packages\fastapi\applications.py", line 269, in __call__
    await super().__call__(scope, receive, send)
  File "C:\Users\tobis\AppData\Local\Packages\PythonSoftwareFoundation.Python.3.7_qbz5n2kfra8p0\LocalCache\local-packages\Python37\site-packages\starlette\applications.py", line 124, in __call__
    await self.middleware_stack(scope, receive, send)
  File "C:\Users\tobis\AppData\Local\Packages\PythonSoftwareFoundation.Python.3.7_qbz5n2kfra8p0\LocalCache\local-packages\Python37\site-packages\starlette\middleware\errors.py", line 184, in __call__
    raise exc
  File "C:\Users\tobis\AppData\Local\Packages\PythonSoftwareFoundation.Python.3.7_qbz5n2kfra8p0\LocalCache\local-packages\Python37\site-packages\starlette\middleware\errors.py", line 162, in __call__
    await self.app(scope, receive, _send)
  File "C:\Users\tobis\AppData\Local\Packages\PythonSoftwareFoundation.Python.3.7_qbz5n2kfra8p0\LocalCache\local-packages\Python37\site-packages\starlette\exceptions.py", line 101, in __call__
    response = await handler(request, exc)
  File ".\main.py", line 15, in handle_user_not_found_exception
    return JSONResponse(status_code=404, detail="User does not exist")
TypeError: __init__() got an unexpected keyword argument 'detail'
ERROR  uvicorn.error   23-07-20 22:25:50.729 Exception in ASGI application
Traceback (most recent call last):
  File "C:\Users\tobis\AppData\Local\Packages\PythonSoftwareFoundation.Python.3.7_qbz5n2kfra8p0\LocalCache\local-packages\Python37\site-packages\starlette\exceptions.py", line 82, in __call__
    await self.app(scope, receive, sender)
  File "C:\Users\tobis\AppData\Local\Packages\PythonSoftwareFoundation.Python.3.7_qbz5n2kfra8p0\LocalCache\local-packages\Python37\site-packages\fastapi\middleware\asyncexitstack.py", line 21, in __call__
    raise e
  File "C:\Users\tobis\AppData\Local\Packages\PythonSoftwareFoundation.Python.3.7_qbz5n2kfra8p0\LocalCache\local-packages\Python37\site-packages\fastapi\middleware\asyncexitstack.py", line 18, in __call__
    await self.app(scope, receive, send)
  File "C:\Users\tobis\AppData\Local\Packages\PythonSoftwareFoundation.Python.3.7_qbz5n2kfra8p0\LocalCache\local-packages\Python37\site-packages\starlette\routing.py", line 670, in __call__
    await route.handle(scope, receive, send)
  File "C:\Users\tobis\AppData\Local\Packages\PythonSoftwareFoundation.Python.3.7_qbz5n2kfra8p0\LocalCache\local-packages\Python37\site-packages\starlette\routing.py", line 266, in handle
    await self.app(scope, receive, send)
  File "C:\Users\tobis\AppData\Local\Packages\PythonSoftwareFoundation.Python.3.7_qbz5n2kfra8p0\LocalCache\local-packages\Python37\site-packages\starlette\routing.py", line 65, in app
    response = await func(request)
  File "C:\Users\tobis\AppData\Local\Packages\PythonSoftwareFoundation.Python.3.7_qbz5n2kfra8p0\LocalCache\local-packages\Python37\site-packages\fastapi\routing.py", line 228, in app
    dependant=dependant, values=values, is_coroutine=is_coroutine
  File "C:\Users\tobis\AppData\Local\Packages\PythonSoftwareFoundation.Python.3.7_qbz5n2kfra8p0\LocalCache\local-packages\Python37\site-packages\fastapi\routing.py", line 160, in run_endpoint_function
    return await dependant.call(**values)
  File ".\app\routes\user.py", line 37, in get_user_by_id
    full_user_profile = await user_service.get_user_info(user_id)
  File ".\app\services\user.py", line 44, in get_user_info
    raise UserNotFound
app.exceptions.UserNotFound

During handling of the above exception, another exception occurred:

Traceback (most recent call last):
  File "C:\Users\tobis\AppData\Local\Packages\PythonSoftwareFoundation.Python.3.7_qbz5n2kfra8p0\LocalCache\local-packages\Python37\site-packages\uvicorn\protocols\http\httptools_impl.py", line 401, in run_asgi
    result = await app(self.scope, self.receive, self.send)
  File "C:\Users\tobis\AppData\Local\Packages\PythonSoftwareFoundation.Python.3.7_qbz5n2kfra8p0\LocalCache\local-packages\Python37\site-packages\uvicorn\middleware\proxy_headers.py", line 78, in __call__
    return await self.app(scope, receive, send)
  File "C:\Users\tobis\AppData\Local\Packages\PythonSoftwareFoundation.Python.3.7_qbz5n2kfra8p0\LocalCache\local-packages\Python37\site-packages\fastapi\applications.py", line 269, in __call__
    await super().__call__(scope, receive, send)
  File "C:\Users\tobis\AppData\Local\Packages\PythonSoftwareFoundation.Python.3.7_qbz5n2kfra8p0\LocalCache\local-packages\Python37\site-packages\starlette\applications.py", line 124, in __call__
    await self.middleware_stack(scope, receive, send)
  File "C:\Users\tobis\AppData\Local\Packages\PythonSoftwareFoundation.Python.3.7_qbz5n2kfra8p0\LocalCache\local-packages\Python37\site-packages\starlette\middleware\errors.py", line 184, in __call__
    raise exc
  File "C:\Users\tobis\AppData\Local\Packages\PythonSoftwareFoundation.Python.3.7_qbz5n2kfra8p0\LocalCache\local-packages\Python37\site-packages\starlette\middleware\errors.py", line 162, in __call__
    await self.app(scope, receive, _send)
  File "C:\Users\tobis\AppData\Local\Packages\PythonSoftwareFoundation.Python.3.7_qbz5n2kfra8p0\LocalCache\local-packages\Python37\site-packages\starlette\exceptions.py", line 101, in __call__
    response = await handler(request, exc)
  File ".\main.py", line 15, in handle_user_not_found_exception
    return JSONResponse(status_code=404, detail="User does not exist")
TypeError: __init__() got an unexpected keyword argument 'detail'
INFO   uvicorn.error   23-07-20 22:26:02.297 Started server process [3508]
INFO   uvicorn.error   23-07-20 22:26:02.298 Waiting for application startup.
INFO   uvicorn.error   23-07-20 22:26:02.300 Application startup complete.
INFO   uvicorn.error   23-07-20 22:27:05.260 Started server process [8844]
INFO   uvicorn.error   23-07-20 22:27:05.261 Waiting for application startup.
INFO   uvicorn.error   23-07-20 22:27:05.270 Application startup complete.
INFO   uvicorn.error   23-07-20 22:27:11.742 Started server process [8]
INFO   uvicorn.error   23-07-20 22:27:11.743 Waiting for application startup.
INFO   uvicorn.error   23-07-20 22:27:11.744 Application startup complete.
INFO   uvicorn.error   23-07-20 22:27:25.385 Started server process [13584]
INFO   uvicorn.error   23-07-20 22:27:25.387 Waiting for application startup.
INFO   uvicorn.error   23-07-20 22:27:25.387 Application startup complete.
INFO   uvicorn.error   23-07-20 22:27:47.614 Started server process [11492]
INFO   uvicorn.error   23-07-20 22:27:47.615 Waiting for application startup.
INFO   uvicorn.error   23-07-20 22:27:47.616 Application startup complete.
INFO   uvicorn.error   23-07-20 22:28:05.311 Started server process [4292]
INFO   uvicorn.error   23-07-20 22:28:05.312 Waiting for application startup.
INFO   uvicorn.error   23-07-20 22:28:05.313 Application startup complete.
INFO   uvicorn.error   23-07-20 22:28:22.533 Started server process [13292]
INFO   uvicorn.error   23-07-20 22:28:22.534 Waiting for application startup.
INFO   uvicorn.error   23-07-20 22:28:22.536 Application startup complete.
INFO   uvicorn.error   23-07-20 22:28:41.150 Started server process [15944]
INFO   uvicorn.error   23-07-20 22:28:41.151 Waiting for application startup.
INFO   uvicorn.error   23-07-20 22:28:41.152 Application startup complete.
ERROR  uvicorn.error   23-07-20 22:28:49.723 Exception in ASGI application
Traceback (most recent call last):
  File "C:\Users\tobis\AppData\Local\Packages\PythonSoftwareFoundation.Python.3.7_qbz5n2kfra8p0\LocalCache\local-packages\Python37\site-packages\uvicorn\protocols\http\httptools_impl.py", line 401, in run_asgi
    result = await app(self.scope, self.receive, self.send)
  File "C:\Users\tobis\AppData\Local\Packages\PythonSoftwareFoundation.Python.3.7_qbz5n2kfra8p0\LocalCache\local-packages\Python37\site-packages\uvicorn\middleware\proxy_headers.py", line 78, in __call__
    return await self.app(scope, receive, send)
  File "C:\Users\tobis\AppData\Local\Packages\PythonSoftwareFoundation.Python.3.7_qbz5n2kfra8p0\LocalCache\local-packages\Python37\site-packages\fastapi\applications.py", line 269, in __call__
    await super().__call__(scope, receive, send)
  File "C:\Users\tobis\AppData\Local\Packages\PythonSoftwareFoundation.Python.3.7_qbz5n2kfra8p0\LocalCache\local-packages\Python37\site-packages\starlette\applications.py", line 124, in __call__
    await self.middleware_stack(scope, receive, send)
  File "C:\Users\tobis\AppData\Local\Packages\PythonSoftwareFoundation.Python.3.7_qbz5n2kfra8p0\LocalCache\local-packages\Python37\site-packages\starlette\middleware\errors.py", line 184, in __call__
    raise exc
  File "C:\Users\tobis\AppData\Local\Packages\PythonSoftwareFoundation.Python.3.7_qbz5n2kfra8p0\LocalCache\local-packages\Python37\site-packages\starlette\middleware\errors.py", line 162, in __call__
    await self.app(scope, receive, _send)
  File "C:\Users\tobis\AppData\Local\Packages\PythonSoftwareFoundation.Python.3.7_qbz5n2kfra8p0\LocalCache\local-packages\Python37\site-packages\starlette\exceptions.py", line 93, in __call__
    raise exc
  File "C:\Users\tobis\AppData\Local\Packages\PythonSoftwareFoundation.Python.3.7_qbz5n2kfra8p0\LocalCache\local-packages\Python37\site-packages\starlette\exceptions.py", line 82, in __call__
    await self.app(scope, receive, sender)
  File "C:\Users\tobis\AppData\Local\Packages\PythonSoftwareFoundation.Python.3.7_qbz5n2kfra8p0\LocalCache\local-packages\Python37\site-packages\fastapi\middleware\asyncexitstack.py", line 21, in __call__
    raise e
  File "C:\Users\tobis\AppData\Local\Packages\PythonSoftwareFoundation.Python.3.7_qbz5n2kfra8p0\LocalCache\local-packages\Python37\site-packages\fastapi\middleware\asyncexitstack.py", line 18, in __call__
    await self.app(scope, receive, send)
  File "C:\Users\tobis\AppData\Local\Packages\PythonSoftwareFoundation.Python.3.7_qbz5n2kfra8p0\LocalCache\local-packages\Python37\site-packages\starlette\routing.py", line 670, in __call__
    await route.handle(scope, receive, send)
  File "C:\Users\tobis\AppData\Local\Packages\PythonSoftwareFoundation.Python.3.7_qbz5n2kfra8p0\LocalCache\local-packages\Python37\site-packages\starlette\routing.py", line 266, in handle
    await self.app(scope, receive, send)
  File "C:\Users\tobis\AppData\Local\Packages\PythonSoftwareFoundation.Python.3.7_qbz5n2kfra8p0\LocalCache\local-packages\Python37\site-packages\starlette\routing.py", line 65, in app
    response = await func(request)
  File "C:\Users\tobis\AppData\Local\Packages\PythonSoftwareFoundation.Python.3.7_qbz5n2kfra8p0\LocalCache\local-packages\Python37\site-packages\fastapi\routing.py", line 228, in app
    dependant=dependant, values=values, is_coroutine=is_coroutine
  File "C:\Users\tobis\AppData\Local\Packages\PythonSoftwareFoundation.Python.3.7_qbz5n2kfra8p0\LocalCache\local-packages\Python37\site-packages\fastapi\routing.py", line 160, in run_endpoint_function
    return await dependant.call(**values)
  File ".\app\routes\user.py", line 37, in get_user_by_id
    full_user_profile = await user_service.get_user_info(user_id)
  File ".\app\services\user.py", line 44, in get_user_info
    raise UserNotFound
app.exceptions.UserNotFound
INFO   uvicorn.error   23-07-20 22:29:18.712 Started server process [7768]
INFO   uvicorn.error   23-07-20 22:29:18.713 Waiting for application startup.
INFO   uvicorn.error   23-07-20 22:29:18.714 Application startup complete.
INFO   uvicorn.error   23-07-20 22:30:14.964 Started server process [12748]
INFO   uvicorn.error   23-07-20 22:30:14.965 Waiting for application startup.
INFO   uvicorn.error   23-07-20 22:30:14.966 Application startup complete.
INFO   uvicorn.error   23-07-20 22:30:29.445 Started server process [4748]
INFO   uvicorn.error   23-07-20 22:30:29.447 Waiting for application startup.
INFO   uvicorn.error   23-07-20 22:30:29.448 Application startup complete.
INFO   uvicorn.error   23-07-20 22:30:33.912 Started server process [4252]
INFO   uvicorn.error   23-07-20 22:30:33.914 Waiting for application startup.
INFO   uvicorn.error   23-07-20 22:30:33.915 Application startup complete.
INFO   uvicorn.error   23-07-20 22:31:17.202 Started server process [4384]
INFO   uvicorn.error   23-07-20 22:31:17.203 Waiting for application startup.
INFO   uvicorn.error   23-07-20 22:31:17.203 Application startup complete.
INFO   uvicorn.error   23-07-20 22:32:10.360 Started server process [4288]
INFO   uvicorn.error   23-07-20 22:32:10.363 Waiting for application startup.
INFO   uvicorn.error   23-07-20 22:32:10.366 Application startup complete.
INFO   uvicorn.error   23-07-20 22:32:23.989 Started server process [13184]
INFO   uvicorn.error   23-07-20 22:32:23.992 Waiting for application startup.
INFO   uvicorn.error   23-07-20 22:32:23.999 Application startup complete.
INFO   uvicorn.error   23-07-20 22:32:47.902 Started server process [4788]
INFO   uvicorn.error   23-07-20 22:32:47.903 Waiting for application startup.
INFO   uvicorn.error   23-07-20 22:32:47.904 Application startup complete.
INFO   uvicorn.error   23-07-20 22:33:14.284 Started server process [9480]
INFO   uvicorn.error   23-07-20 22:33:14.285 Waiting for application startup.
INFO   uvicorn.error   23-07-20 22:33:14.285 Application startup complete.
ERROR  app.exception_handlers 23-07-20 22:33:18.306 Non-existent user_id: 2 was requested
INFO   uvicorn.error   23-07-20 22:33:40.704 Started server process [14020]
INFO   uvicorn.error   23-07-20 22:33:40.706 Waiting for application startup.
INFO   uvicorn.error   23-07-20 22:33:40.707 Application startup complete.
ERROR  app.exception_handlers 23-07-20 22:33:40.709 Non-existent user_id: 2 was requested
INFO   uvicorn.error   23-07-20 22:34:04.368 Started server process [12744]
INFO   uvicorn.error   23-07-20 22:34:04.369 Waiting for application startup.
INFO   uvicorn.error   23-07-20 22:34:04.370 Application startup complete.
INFO   uvicorn.error   23-07-20 22:36:09.579 Started server process [14576]
INFO   uvicorn.error   23-07-20 22:36:09.580 Waiting for application startup.
INFO   uvicorn.error   23-07-20 22:36:09.581 Application startup complete.
INFO   uvicorn.error   23-07-25 21:01:25.784 Started server process [6504]
INFO   uvicorn.error   23-07-25 21:01:25.788 Waiting for application startup.
INFO   uvicorn.error   23-07-25 21:01:25.790 Application startup complete.
INFO   uvicorn.error   23-07-25 21:05:26.409 Started server process [5508]
INFO   uvicorn.error   23-07-25 21:05:26.412 Waiting for application startup.
INFO   uvicorn.error   23-07-25 21:05:26.416 Application startup complete.
INFO   uvicorn.error   23-07-25 21:07:06.736 Started server process [10544]
INFO   uvicorn.error   23-07-25 21:07:06.753 Waiting for application startup.
INFO   uvicorn.error   23-07-25 21:07:06.757 Application startup complete.
INFO   uvicorn.error   23-07-25 21:08:00.387 Started server process [15336]
INFO   uvicorn.error   23-07-25 21:08:00.388 Waiting for application startup.
INFO   uvicorn.error   23-07-25 21:08:00.391 Application startup complete.
INFO   uvicorn.error   23-07-25 21:08:19.196 Started server process [8284]
INFO   uvicorn.error   23-07-25 21:08:19.198 Waiting for application startup.
INFO   uvicorn.error   23-07-25 21:08:19.199 Application startup complete.
INFO   uvicorn.error   23-07-25 21:11:44.084 Started server process [7952]
INFO   uvicorn.error   23-07-25 21:11:44.098 Waiting for application startup.
INFO   uvicorn.error   23-07-25 21:11:44.105 Application startup complete.
INFO   uvicorn.error   23-07-25 21:12:00.319 Started server process [2544]
INFO   uvicorn.error   23-07-25 21:12:00.327 Waiting for application startup.
INFO   uvicorn.error   23-07-25 21:12:00.328 Application startup complete.
INFO   uvicorn.error   23-07-25 21:15:18.489 Started server process [8512]
INFO   uvicorn.error   23-07-25 21:15:18.490 Waiting for application startup.
INFO   uvicorn.error   23-07-25 21:15:18.491 Application startup complete.
INFO   uvicorn.error   23-07-25 21:16:10.731 Started server process [9836]
INFO   uvicorn.error   23-07-25 21:16:10.734 Waiting for application startup.
INFO   uvicorn.error   23-07-25 21:16:10.736 Application startup complete.
INFO   uvicorn.error   23-07-25 21:16:58.437 Started server process [8844]
INFO   uvicorn.error   23-07-25 21:16:58.439 Waiting for application startup.
INFO   uvicorn.error   23-07-25 21:16:58.440 Application startup complete.
INFO   uvicorn.error   23-07-25 21:19:10.493 Started server process [836]
INFO   uvicorn.error   23-07-25 21:19:10.494 Waiting for application startup.
INFO   uvicorn.error   23-07-25 21:19:10.495 Application startup complete.
INFO   uvicorn.error   23-07-25 21:20:07.136 Started server process [8768]
INFO   uvicorn.error   23-07-25 21:20:07.137 Waiting for application startup.
INFO   uvicorn.error   23-07-25 21:20:07.137 Application startup complete.
INFO   uvicorn.error   23-07-25 21:21:55.927 Started server process [14016]
INFO   uvicorn.error   23-07-25 21:21:55.928 Waiting for application startup.
INFO   uvicorn.error   23-07-25 21:21:55.929 Application startup complete.
INFO   uvicorn.error   23-07-25 21:23:38.746 Started server process [13772]
INFO   uvicorn.error   23-07-25 21:23:38.747 Waiting for application startup.
INFO   uvicorn.error   23-07-25 21:23:38.748 Application startup complete.
INFO   uvicorn.error   23-07-25 21:25:36.367 Started server process [8512]
INFO   uvicorn.error   23-07-25 21:25:36.367 Waiting for application startup.
INFO   uvicorn.error   23-07-25 21:25:36.368 Application startup complete.
INFO   uvicorn.error   23-07-25 21:25:45.379 Started server process [10248]
INFO   uvicorn.error   23-07-25 21:25:45.380 Waiting for application startup.
INFO   uvicorn.error   23-07-25 21:25:45.381 Application startup complete.
